Workbook

Sheet HOUSE DASHBOARD
A1: 2026 ELECTION SIMULATOR / HOUSE | 435 DISTRICTS
A2: Adjust national conditions and Democratic vote shares; live seat totals update automatically.
A4: NATIONAL ENVIRONMENT SIMULATOR | G4: LIVE SEAT COUNT! 435 HOUSE SEATS IN TOTAL: 218 VOTES NEEDED FOR A MAJORITY. 2024 U.S. House: 220 R 215 D
A5: National generic ballot baseline (positive values indicate Democratic lead) | B5: 8.4 | C5: 8.7 | D5: =IF(B11="Demographic-driven",0,IF(B9="Custom",B5,IFERROR(IF(LEFT(B9,1)="R",-1,1)*VALUE(MID(B9,3,20)),B5))-8.7)+B7 -> -0.3 | E5: 2024 baseline context; preset and teal inputs determine scenario | G5: Democratic seats | I5: Republican seats
A6: Demographic scenario | B6: All edited groups | E6: Active demographics: RACE + EDUCATION only | G6: =COUNTIF(I31:I465,"D") -> 235 | I6: =COUNTIF(I31:I465,"R") -> 200
A7: Additional swing (pp) | B7: 0 | E7: 0 = no extra adjustment
A8: Implied national D−R (after demographic changes) | B8: =8.7+D5+(F26+F27)/2 -> 8.4 | E8: Implied national vote margin reflects scenario settings.
A9: Generic ballot preset | B9: Custom | C9: Preset (generic ballot mode only) | E9: Custom uses teal B5; select D/R preset to override B5. | G9: D seat change | H9: =G6-215 -> 20 | I9: R seat change | J9: =-H9 -> -20
A10: Baseline method | B10: Uniform swing | C10: Each contest has its own 2026 forecast baseline | E10: Historical race margins stay fixed in DATA sheets. | G10: 435 House districts; majority = 218.
A11: National environment mode | B11: Generic ballot | D11: 2024 presidential baseline (D−R pp) | E11: Mode: Generic ballot combines the ballot swing with vote-share changes; Demographic-driven uses vote-share changes alone.
G12: Ballot-locked seats | H12: =COUNTIF(V31:V465,"D")+COUNTIF(V31:V465,"R") -> 14
A13: RACE / ETHNICITY | B13: EDIT D% for 2026 National % | C13: 2024 National Baseline (R+1.5) | D13: 2020 National Baseline (D+ 4.5) | E13: 2018 National House (D+8.4) | F13: Applied D% | I13: 2018 US D% (D+8.4) | J13: Race | K13: 2024 reference % | L13: 2026 entered % | M13: Applied % | N13: Change pp
A14: White (non-Hispanic) | B14: 42.4 | C14: 42.4 | D14: 42 | E14: 45 | F14: =B14 -> 42.4 | G14: Race | I14: 44 | J14: White non-Hispanic | K14: 75 | L14: 75 | M14: =IF($P$14="2024 baseline",K14,IFERROR(100*L14/SUM($L$14:$L$18),K14)) -> 75 | N14: =M14-K14 -> 0 | O14: Race reset
A15: Hispanic / Latino | B15: 54.2 | C15: 54.2 | D15: 63 | E15: 67 | F15: =B15 -> 54.2 | I15: 69 | J15: Hispanic / Latino | K15: 10 | L15: 10 | M15: =IF($P$14="2024 baseline",K15,IFERROR(100*L15/SUM($L$14:$L$18),K15)) -> 10 | N15: =M15-K15 -> 0
A16: Black | B16: 85.4 | C16: 85.4 | D16: 90 | E16: 91 | F16: =B16 -> 85.4 | I16: 90 | J16: Black | K16: 10 | L16: 10 | M16: =IF($P$14="2024 baseline",K16,IFERROR(100*L16/SUM($L$14:$L$18),K16)) -> 10 | N16: =M16-K16 -> 0
A17: Asian | B17: 60.7 | C17: 60.7 | D17: 64 | E17: 62 | F17: =B17 -> 60.7 | I17: 77 | J17: Asian | K17: 2.3011941 | L17: 2.3011941 | M17: =IF($P$14="2024 baseline",K17,IFERROR(100*L17/SUM($L$14:$L$18),K17)) -> 2.3011941 | N17: =M17-K17 -> 0
A18: Other / unclassified | B18: 53.5 | C18: 53.5 | F18: =B18 -> 53.5 | J18: Other / unclassified | K18: 2.6988059 | L18: 2.6988059 | M18: =IF($P$14="2024 baseline",K18,IFERROR(100*L18/SUM($L$14:$L$18),K18)) -> 2.6988059 | N18: =M18-K18 -> 0
A20: EDUCATION GROUP | B20: EDIT D % | C20: 2024 National Baseline (R+1.5) | D20: 2020 National Baseline (D+ 4.5) | E20: 2018 National House (D+8.4) | F20: Applied D% | J20: Education | K20: 2024 electorate % | L20: 2026 entered % | M20: Applied % | N20: Change pp
A21: College degree (BA+) | B21: 55.6 | C21: 55.6 | D21: 56 | E21: 57 | F21: =B21 -> 55.6 | G21: Education | J21: College degree (BA+) | K21: 42 | L21: 42 | M21: =IF($P$21="2024 baseline",K21,L21) -> 42 | N21: =M21-K21 -> 0 | O21: Education reset | P21: Use entered
A22: Without BA degree | B22: 44.9 | C22: 44.9 | D22: 49 | E22: 52 | F22: =B22 -> 44.9 | J22: No BA degree | K22: 58 | L22: =100-L21 -> 58 | M22: =IF($P$21="2024 baseline",K22,L22) -> 58 | N22: =M22-K22 -> 0
A23: Edit only teal B inputs. Fixed historical D% comparisons never change the simulation.
A25: Ballot source: 270toWin 2026 uncontested House races; California SOS top-two election rules. | B25: =LARGE(H31:H465,218) -> 8.24 | D25: Tipping contest | E25: =INDEX(A31:A465,MATCH(218,M31:M465,0)) -> WI-03 | G25: D seats needed | H25: =MAX(0,218-G6) -> 0 | I25: R seats needed | J25: =MAX(0,218-I6) -> 18
E26: National race shift (pp) | F26: =2*(75*(B14-42.4)+10*(B15-54.2)+10*(B16-85.4)+2.301194118*(B17-60.7)+2.698805882*(B18-53.5))/100 -> 0
A27: 2026 interactive scenario • historical baseline fixed • teal cells are controls | E27: National education shift (pp) | F27: =2*(42*(B21-55.6)+58*(B22-44.9))/100 -> 0
A30: District / state | B30: Original D−R | C30: National Δ | D30: Race Δ | E30: Education Δ | F30: Income (excluded) | G30: Race + Education Δ | H30: SCENARIO D−R | I30: Party | J30: Baseline holder / reference | K30: Flip vs reference | L30: Display margin | M30: D margin rank | N30: Absolute margin | O30: Closeness rank | P30: Source baseline D−R | Q30: Source election / proxy | R30: Scenario − historical | S30: Legacy forecast − baseline | T30: Scenario − legacy forecast | U30: 2026 BALLOT STATUS | V30: LOCKED PARTY | W30: Ballot details / source | X30: Override rationale
A31: ='HOUSE DATA'!A4 -> AK-AL | B31: ='HOUSE DATA'!B4 -> 8.1315242 | C31: =$D$5 -> -0.3 | D31: =2*('HOUSE DATA'!D4*('HOUSE DASHBOARD'!$B$14-42.4)+'HOUSE DATA'!E4*('HOUSE DASHBOARD'!$B$15-54.2)+'HOUSE DATA'!F4*('HOUSE DASHBOARD'!$B$16-85.4)+'HOUSE DATA'!G4*('HOUSE DASHBOARD'!$B$17-60.7)+'HOUSE DATA'!H4*('HOUSE DASHBOARD'!$B$18-53.5))/100 -> 0 | E31: =2*('HOUSE DATA'!I4*('HOUSE DASHBOARD'!$B$21-55.6)+(100-'HOUSE DATA'!I4)*('HOUSE DASHBOARD'!$B$22-44.9))/100 -> 0 | F31: =0 -> 0 | G31: =(D31+E31)/2 -> 0 | H31: ='HOUSE DATA'!C4+C31+G31 -> 9.92 | I31: =IF(V31="D","D",IF(V31="R","R",IF(H31>=0,"D","R"))) -> D | J31: ='HOUSE DATA'!K4 -> R | K31: =IF(I31=J31,"—",J31&" → "&I31) -> R → D | L31: =IF(V31="D","D — BALLOT LOCK",IF(V31="R","R — BALLOT LOCK",IF(H31>=0,"D+"&TEXT(H31,"0.00"),"R+"&TEXT(-H31,"0.00")))) -> D+9.92 | M31: =COUNTIF($H$31:$H$465,">"&H31)+COUNTIF($H$31:H31,H31) -> 213 | N31: =IF(V31<>"",100,ABS(H31)) -> 9.92 | O31: =COUNTIF($N$31:$N$465,"<"&N31)+COUNTIF($N$31:N31,N31) -> 85 | P31: ='HOUSE DATA'!M4 -> -1.04 | Q31: ='HOUSE DATA'!N4 -> 2024 HOUSE / prior substitute | R31: =H31-P31 -> 10.96 | S31: =B31-P31 -> 9.1715242 | T31: =H31-B31 -> 1.7884758 | U31: Contested | W31: Both major parties or other ballot arrangement | X31: Standard model; verify if ballot changes
A32: ='HOUSE DATA'!A5 -> AL-01 | B32: ='HOUSE DATA'!B5 -> -24.724556 | C32: =$D$5 -> -0.3 | D32: =2*('HOUSE DATA'!D5*('HOUSE DASHBOARD'!$B$14-42.4)+'HOUSE DATA'!E5*('HOUSE DASHBOARD'!$B$15-54.2)+'HOUSE DATA'!F5*('HOUSE DASHBOARD'!$B$16-85.4)+'HOUSE DATA'!G5*('HOUSE DASHBOARD'!$B$17-60.7)+'HOUSE DATA'!H5*('HOUSE DASHBOARD'!$B$18-53.5))/100 -> 0 | E32: =2*('HOUSE DATA'!I5*('HOUSE DASHBOARD'!$B$21-55.6)+(100-'HOUSE DATA'!I5)*('HOUSE DASHBOARD'!$B$22-44.9))/100 -> 0 | F32: =0 -> 0 | G32: =(D32+E32)/2 -> 0 | H32: ='HOUSE DATA'!C5+C32+G32 -> -25.47 | I32: =IF(V32="D","D",IF(V32="R","R",IF(H32>=0,"D","R"))) -> R | J32: ='HOUSE DATA'!K5 -> R | K32: =IF(I32=J32,"—",J32&" → "&I32) -> — | L32: =IF(V32="D","D — BALLOT LOCK",IF(V32="R","R — BALLOT LOCK",IF(H32>=0,"D+"&TEXT(H32,"0.00"),"R+"&TEXT(-H32,"0.00")))) -> R+25.47 | M32: =COUNTIF($H$31:$H$465,">"&H32)+COUNTIF($H$31:H32,H32) -> 385 | N32: =IF(V32<>"",100,ABS(H32)) -> 25.47 | O32: =COUNTIF($N$31:$N$465,"<"&N32)+COUNTIF($N$31:N32,N32) -> 242 | P32: ='HOUSE DATA'!M5 -> -36.02 | Q32: ='HOUSE DATA'!N5 -> 2024 PRESIDENT (open seat) | R32: =H32-P32 -> 10.55 | S32: =B32-P32 -> 11.295444 | T32: =H32-B32 -> -0.74544416 | U32: Contested | W32: Both major parties or other ballot arrangement | X32: Standard model; verify if ballot changes
A33: ='HOUSE DATA'!A6 -> AL-02 | B33: ='HOUSE DATA'!B6 -> -2.8761422 | C33: =$D$5 -> -0.3 | D33: =2*('HOUSE DATA'!D6*('HOUSE DASHBOARD'!$B$14-42.4)+'HOUSE DATA'!E6*('HOUSE DASHBOARD'!$B$15-54.2)+'HOUSE DATA'!F6*('HOUSE DASHBOARD'!$B$16-85.4)+'HOUSE DATA'!G6*('HOUSE DASHBOARD'!$B$17-60.7)+'HOUSE DATA'!H6*('HOUSE DASHBOARD'!$B$18-53.5))/100 -> 0 | E33: =2*('HOUSE DATA'!I6*('HOUSE DASHBOARD'!$B$21-55.6)+(100-'HOUSE DATA'!I6)*('HOUSE DASHBOARD'!$B$22-44.9))/100 -> 0 | F33: =0 -> 0 | G33: =(D33+E33)/2 -> 0 | H33: ='HOUSE DATA'!C6+C33+G33 -> -3.4990495 | I33: =IF(V33="D","D",IF(V33="R","R",IF(H33>=0,"D","R"))) -> R | J33: ='HOUSE DATA'!K6 -> D | K33: =IF(I33=J33,"—",J33&" → "&I33) -> D → R | L33: =IF(V33="D","D — BALLOT LOCK",IF(V33="R","R — BALLOT LOCK",IF(H33>=0,"D+"&TEXT(H33,"0.00"),"R+"&TEXT(-H33,"0.00")))) -> R+3.50 | M33: =COUNTIF($H$31:$H$465,">"&H33)+COUNTIF($H$31:H33,H33) -> 258 | N33: =IF(V33<>"",100,ABS(H33)) -> 3.4990495 | O33: =COUNTIF($N$31:$N$465,"<"&N33)+COUNTIF($N$31:N33,N33) -> 30 | P33: ='HOUSE DATA'!M6 -> -14.45905 | Q33: ='HOUSE DATA'!N6 -> 2024 HOUSE / prior substitute | R33: =H33-P33 -> 10.96 | S33: =B33-P33 -> 11.582907 | T33: =H33-B33 -> -0.62290739 | U33: Contested | W33: Both major parties or other ballot arrangement | X33: Standard model; verify if ballot changes
A34: ='HOUSE DATA'!A7 -> AL-03 | B34: ='HOUSE DATA'!B7 -> -35.422944 | C34: =$D$5 -> -0.3 | D34: =2*('HOUSE DATA'!D7*('HOUSE DASHBOARD'!$B$14-42.4)+'HOUSE DATA'!E7*('HOUSE DASHBOARD'!$B$15-54.2)+'HOUSE DATA'!F7*('HOUSE DASHBOARD'!$B$16-85.4)+'HOUSE DATA'!G7*('HOUSE DASHBOARD'!$B$17-60.7)+'HOUSE DATA'!H7*('HOUSE DASHBOARD'!$B$18-53.5))/100 -> 0 | E34: =2*('HOUSE DATA'!I7*('HOUSE DASHBOARD'!$B$21-55.6)+(100-'HOUSE DATA'!I7)*('HOUSE DASHBOARD'!$B$22-44.9))/100 -> 0 | F34: =0 -> 0 | G34: =(D34+E34)/2 -> 0 | H34: ='HOUSE DATA'!C7+C34+G34 -> -36.057189 | I34: =IF(V34="D","D",IF(V34="R","R",IF(H34>=0,"D","R"))) -> R | J34: ='HOUSE DATA'!K7 -> R | K34: =IF(I34=J34,"—",J34&" → "&I34) -> — | L34: =IF(V34="D","D — BALLOT LOCK",IF(V34="R","R — BALLOT LOCK",IF(H34>=0,"D+"&TEXT(H34,"0.00"),"R+"&TEXT(-H34,"0.00")))) -> R+36.06 | M34: =COUNTIF($H$31:$H$465,">"&H34)+COUNTIF($H$31:H34,H34) -> 418 | N34: =IF(V34<>"",100,ABS(H34)) -> 36.057189 | O34: =COUNTIF($N$31:$N$465,"<"&N34)+COUNTIF($N$31:N34,N34) -> 317 | P34: ='HOUSE DATA'!M7 -> -47.017189 | Q34: ='HOUSE DATA'!N7 -> 2024 HOUSE / prior substitute | R34: =H34-P34 -> 10.96 | S34: =B34-P34 -> 11.594245 | T34: =H34-B34 -> -0.63424518 | U34: Contested | W34: Both major parties or other ballot arrangement | X34: Standard model; verify if ballot changes
A35: ='HOUSE DATA'!A8 -> AL-04 | B35: ='HOUSE DATA'!B8 -> -56.160299 | C35: =$D$5 -> -0.3 | D35: =2*('HOUSE DATA'!D8*('HOUSE DASHBOARD'!$B$14-42.4)+'HOUSE DATA'!E8*('HOUSE DASHBOARD'!$B$15-54.2)+'HOUSE DATA'!F8*('HOUSE DASHBOARD'!$B$16-85.4)+'HOUSE DATA'!G8*('HOUSE DASHBOARD'!$B$17-60.7)+'HOUSE DATA'!H8*('HOUSE DASHBOARD'!$B$18-53.5))/100 -> 0 | E35: =2*('HOUSE DATA'!I8*('HOUSE DASHBOARD'!$B$21-55.6)+(100-'HOUSE DATA'!I8)*('HOUSE DASHBOARD'!$B$22-44.9))/100 -> 0 | F35: =0 -> 0 | G35: =(D35+E35)/2 -> 0 | H35: ='HOUSE DATA'!C8+C35+G35 -> -56.077412 | I35: =IF(V35="D","D",IF(V35="R","R",IF(H35>=0,"D","R"))) -> R | J35: ='HOUSE DATA'!K8 -> R | K35: =IF(I35=J35,"—",J35&" → "&I35) -> — | L35: =IF(V35="D","D — BALLOT LOCK",IF(V35="R","R — BALLOT LOCK",IF(H35>=0,"D+"&TEXT(H35,"0.00"),"R+"&TEXT(-H35,"0.00")))) -> R+56.08 | M35: =COUNTIF($H$31:$H$465,">"&H35)+COUNTIF($H$31:H35,H35) -> 435 | N35: =IF(V35<>"",100,ABS(H35)) -> 56.077412 | O35: =COUNTIF($N$31:$N$465,"<"&N35)+COUNTIF($N$31:N35,N35) -> 384 | P35: ='HOUSE DATA'!M8 -> -67.037412 | Q35: ='HOUSE DATA'!N8 -> 2024 HOUSE / prior substitute | R35: =H35-P35 -> 10.96 | S35: =B35-P35 -> 10.877113 | T35: =H35-B35 -> 0.082887031 | U35: Contested | W35: Both major parties or other ballot arrangement | X35: Standard model; verify if ballot changes
A36: ='HOUSE DATA'!A9 -> AL-05 | B36: ='HOUSE DATA'!B9 -> -19.750267 | C36: =$D$5 -> -0.3 | D36: =2*('HOUSE DATA'!D9*('HOUSE DASHBOARD'!$B$14-42.4)+'HOUSE DATA'!E9*('HOUSE DASHBOARD'!$B$15-54.2)+'HOUSE DATA'!F9*('HOUSE DASHBOARD'!$B$16-85.4)+'HOUSE DATA'!G9*('HOUSE DASHBOARD'!$B$17-60.7)+'HOUSE DATA'!H9*('HOUSE DASHBOARD'!$B$18-53.5))/100 -> 0 | E36: =2*('HOUSE DATA'!I9*('HOUSE DASHBOARD'!$B$21-55.6)+(100-'HOUSE DATA'!I9)*('HOUSE DASHBOARD'!$B$22-44.9))/100 -> 0 | F36: =0 -> 0 | G36: =(D36+E36)/2 -> 0 | H36: ='HOUSE DATA'!C9+C36+G36 -> -18.571568 | I36: =IF(V36="D","D",IF(V36="R","R",IF(H36>=0,"D","R"))) -> R | J36: ='HOUSE DATA'!K9 -> R | K36: =IF(I36=J36,"—",J36&" → "&I36) -> — | L36: =IF(V36="D","D — BALLOT LOCK",IF(V36="R","R — BALLOT LOCK",IF(H36>=0,"D+"&TEXT(H36,"0.00"),"R+"&TEXT(-H36,"0.00")))) -> R+18.57 | M36: =COUNTIF($H$31:$H$465,">"&H36)+COUNTIF($H$31:H36,H36) -> 350 | N36: =IF(V36<>"",100,ABS(H36)) -> 18.571568 | O36: =COUNTIF($N$31:$N$465,"<"&N36)+COUNTIF($N$31:N36,N36) -> 169 | P36: ='HOUSE DATA'!M9 -> -29.531568 | Q36: ='HOUSE DATA'!N9 -> 2024 HOUSE / prior substitute | R36: =H36-P36 -> 10.96 | S36: =B36-P36 -> 9.781301 | T36: =H36-B36 -> 1.178699 | U36: Contested | W36: Both major parties or other ballot arrangement | X36: Standard model; verify if ballot changes
A37: ='HOUSE DATA'!A10 -> AL-06 | B37: ='HOUSE DATA'!B10 -> -25.430455 | C37: =$D$5 -> -0.3 | D37: =2*('HOUSE DATA'!D10*('HOUSE DASHBOARD'!$B$14-42.4)+'HOUSE DATA'!E10*('HOUSE DASHBOARD'!$B$15-54.2)+'HOUSE DATA'!F10*('HOUSE DASHBOARD'!$B$16-85.4)+'HOUSE DATA'!G10*('HOUSE DASHBOARD'!$B$17-60.7)+'HOUSE DATA'!H10*('HOUSE DASHBOARD'!$B$18-53.5))/100 -> 0 | E37: =2*('HOUSE DATA'!I10*('HOUSE DASHBOARD'!$B$21-55.6)+(100-'HOUSE DATA'!I10)*('HOUSE DASHBOARD'!$B$22-44.9))/100 -> 0 | F37: =0 -> 0 | G37: =(D37+E37)/2 -> 0 | H37: ='HOUSE DATA'!C10+C37+G37 -> -23.796098 | I37: =IF(V37="D","D",IF(V37="R","R",IF(H37>=0,"D","R"))) -> R | J37: ='HOUSE DATA'!K10 -> R | K37: =IF(I37=J37,"—",J37&" → "&I37) -> — | L37: =IF(V37="D","D — BALLOT LOCK",IF(V37="R","R — BALLOT LOCK",IF(H37>=0,"D+"&TEXT(H37,"0.00"),"R+"&TEXT(-H37,"0.00")))) -> R+23.80 | M37: =COUNTIF($H$31:$H$465,">"&H37)+COUNTIF($H$31:H37,H37) -> 380 | N37: =IF(V37<>"",100,ABS(H37)) -> 23.796098 | O37: =COUNTIF($N$31:$N$465,"<"&N37)+COUNTIF($N$31:N37,N37) -> 228 | P37: ='HOUSE DATA'!M10 -> -34.756098 | Q37: ='HOUSE DATA'!N10 -> 2024 HOUSE / prior substitute | R37: =H37-P37 -> 10.96 | S37: =B37-P37 -> 9.3256429 | T37: =H37-B37 -> 1.6343571 | U37: Contested | W37: Both major parties or other ballot arrangement | X37: Standard model; verify if ballot changes
A38: ='HOUSE DATA'!A11 -> AL-07 | B38: ='HOUSE DATA'!B11 -> 30.934189 | C38: =$D$5 -> -0.3 | D38: =2*('HOUSE DATA'!D11*('HOUSE DASHBOARD'!$B$14-42.4)+'HOUSE DATA'!E11*('HOUSE DASHBOARD'!$B$15-54.2)+'HOUSE DATA'!F11*('HOUSE DASHBOARD'!$B$16-85.4)+'HOUSE DATA'!G11*('HOUSE DASHBOARD'!$B$17-60.7)+'HOUSE DATA'!H11*('HOUSE DASHBOARD'!$B$18-53.5))/100 -> 0 | E38: =2*('HOUSE DATA'!I11*('HOUSE DASHBOARD'!$B$21-55.6)+(100-'HOUSE DATA'!I11)*('HOUSE DASHBOARD'!$B$22-44.9))/100 -> 0 | F38: =0 -> 0 | G38: =(D38+E38)/2 -> 0 | H38: ='HOUSE DATA'!C11+C38+G38 -> 28.976194 | I38: =IF(V38="D","D",IF(V38="R","R",IF(H38>=0,"D","R"))) -> D | J38: ='HOUSE DATA'!K11 -> D | K38: =IF(I38=J38,"—",J38&" → "&I38) -> — | L38: =IF(V38="D","D — BALLOT LOCK",IF(V38="R","R — BALLOT LOCK",IF(H38>=0,"D+"&TEXT(H38,"0.00"),"R+"&TEXT(-H38,"0.00")))) -> D+28.98 | M38: =COUNTIF($H$31:$H$465,">"&H38)+COUNTIF($H$31:H38,H38) -> 125 | N38: =IF(V38<>"",100,ABS(H38)) -> 28.976194 | O38: =COUNTIF($N$31:$N$465,"<"&N38)+COUNTIF($N$31:N38,N38) -> 271 | P38: ='HOUSE DATA'!M11 -> 18.016194 | Q38: ='HOUSE DATA'!N11 -> 2024 HOUSE / prior substitute | R38: =H38-P38 -> 10.96 | S38: =B38-P38 -> 12.917994 | T38: =H38-B38 -> -1.9579945 | U38: Contested | W38: Both major parties or other ballot arrangement | X38: Standard model; verify if ballot changes
A39: ='HOUSE DATA'!A12 -> AR-01 | B39: ='HOUSE DATA'!B12 -> -39.099402 | C39: =$D$5 -> -0.3 | D39: =2*('HOUSE DATA'!D12*('HOUSE DASHBOARD'!$B$14-42.4)+'HOUSE DATA'!E12*('HOUSE DASHBOARD'!$B$15-54.2)+'HOUSE DATA'!F12*('HOUSE DASHBOARD'!$B$16-85.4)+'HOUSE DATA'!G12*('HOUSE DASHBOARD'!$B$17-60.7)+'HOUSE DATA'!H12*('HOUSE DASHBOARD'!$B$18-53.5))/100 -> 0 | E39: =2*('HOUSE DATA'!I12*('HOUSE DASHBOARD'!$B$21-55.6)+(100-'HOUSE DATA'!I12)*('HOUSE DASHBOARD'!$B$22-44.9))/100 -> 0 | F39: =0 -> 0 | G39: =(D39+E39)/2 -> 0 | H39: ='HOUSE DATA'!C12+C39+G39 -> -39.5 | I39: =IF(V39="D","D",IF(V39="R","R",IF(H39>=0,"D","R"))) -> R | J39: ='HOUSE DATA'!K12 -> R | K39: =IF(I39=J39,"—",J39&" → "&I39) -> — | L39: =IF(V39="D","D — BALLOT LOCK",IF(V39="R","R — BALLOT LOCK",IF(H39>=0,"D+"&TEXT(H39,"0.00"),"R+"&TEXT(-H39,"0.00")))) -> R+39.50 | M39: =COUNTIF($H$31:$H$465,">"&H39)+COUNTIF($H$31:H39,H39) -> 426 | N39: =IF(V39<>"",100,ABS(H39)) -> 39.5 | O39: =COUNTIF($N$31:$N$465,"<"&N39)+COUNTIF($N$31:N39,N39) -> 335 | P39: ='HOUSE DATA'!M12 -> -50.46 | Q39: ='HOUSE DATA'!N12 -> 2024 HOUSE / prior substitute | R39: =H39-P39 -> 10.96 | S39: =B39-P39 -> 11.360598 | T39: =H39-B39 -> -0.40059838 | U39: Contested | W39: Both major parties or other ballot arrangement | X39: Standard model; verify if ballot changes
A40: ='HOUSE DATA'!A13 -> AR-02 | B40: ='HOUSE DATA'!B13 -> -6.9580952 | C40: =$D$5 -> -0.3 | D40: =2*('HOUSE DATA'!D13*('HOUSE DASHBOARD'!$B$14-42.4)+'HOUSE DATA'!E13*('HOUSE DASHBOARD'!$B$15-54.2)+'HOUSE DATA'!F13*('HOUSE DASHBOARD'!$B$16-85.4)+'HOUSE DATA'!G13*('HOUSE DASHBOARD'!$B$17-60.7)+'HOUSE DATA'!H13*('HOUSE DASHBOARD'!$B$18-53.5))/100 -> 0 | E40: =2*('HOUSE DATA'!I13*('HOUSE DASHBOARD'!$B$21-55.6)+(100-'HOUSE DATA'!I13)*('HOUSE DASHBOARD'!$B$22-44.9))/100 -> 0 | F40: =0 -> 0 | G40: =(D40+E40)/2 -> 0 | H40: ='HOUSE DATA'!C13+C40+G40 -> -6.9 | I40: =IF(V40="D","D",IF(V40="R","R",IF(H40>=0,"D","R"))) -> R | J40: ='HOUSE DATA'!K13 -> R | K40: =IF(I40=J40,"—",J40&" → "&I40) -> — | L40: =IF(V40="D","D — BALLOT LOCK",IF(V40="R","R — BALLOT LOCK",IF(H40>=0,"D+"&TEXT(H40,"0.00"),"R+"&TEXT(-H40,"0.00")))) -> R+6.90 | M40: =COUNTIF($H$31:$H$465,">"&H40)+COUNTIF($H$31:H40,H40) -> 280 | N40: =IF(V40<>"",100,ABS(H40)) -> 6.9 | O40: =COUNTIF($N$31:$N$465,"<"&N40)+COUNTIF($N$31:N40,N40) -> 57 | P40: ='HOUSE DATA'!M13 -> -17.86 | Q40: ='HOUSE DATA'!N13 -> 2024 HOUSE / prior substitute | R40: =H40-P40 -> 10.96 | S40: =B40-P40 -> 10.901905 | T40: =H40-B40 -> 0.058095199 | U40: Contested | W40: Both major parties or other ballot arrangement | X40: Standard model; verify if ballot changes
A41: ='HOUSE DATA'!A14 -> AR-03 | B41: ='HOUSE DATA'!B14 -> -23.054684 | C41: =$D$5 -> -0.3 | D41: =2*('HOUSE DATA'!D14*('HOUSE DASHBOARD'!$B$14-42.4)+'HOUSE DATA'!E14*('HOUSE DASHBOARD'!$B$15-54.2)+'HOUSE DATA'!F14*('HOUSE DASHBOARD'!$B$16-85.4)+'HOUSE DATA'!G14*('HOUSE DASHBOARD'!$B$17-60.7)+'HOUSE DATA'!H14*('HOUSE DASHBOARD'!$B$18-53.5))/100 -> 0 | E41: =2*('HOUSE DATA'!I14*('HOUSE DASHBOARD'!$B$21-55.6)+(100-'HOUSE DATA'!I14)*('HOUSE DASHBOARD'!$B$22-44.9))/100 -> 0 | F41: =0 -> 0 | G41: =(D41+E41)/2 -> 0 | H41: ='HOUSE DATA'!C14+C41+G41 -> -22.56 | I41: =IF(V41="D","D",IF(V41="R","R",IF(H41>=0,"D","R"))) -> R | J41: ='HOUSE DATA'!K14 -> R | K41: =IF(I41=J41,"—",J41&" → "&I41) -> — | L41: =IF(V41="D","D — BALLOT LOCK",IF(V41="R","R — BALLOT LOCK",IF(H41>=0,"D+"&TEXT(H41,"0.00"),"R+"&TEXT(-H41,"0.00")))) -> R+22.56 | M41: =COUNTIF($H$31:$H$465,">"&H41)+COUNTIF($H$31:H41,H41) -> 373 | N41: =IF(V41<>"",100,ABS(H41)) -> 22.56 | O41: =COUNTIF($N$31:$N$465,"<"&N41)+COUNTIF($N$31:N41,N41) -> 215 | P41: ='HOUSE DATA'!M14 -> -33.52 | Q41: ='HOUSE DATA'!N14 -> 2024 HOUSE / prior substitute | R41: =H41-P41 -> 10.96 | S41: =B41-P41 -> 10.465316 | T41: =H41-B41 -> 0.49468375 | U41: Contested | W41: Both major parties or other ballot arrangement | X41: Standard model; verify if ballot changes
A42: ='HOUSE DATA'!A15 -> AR-04 | B42: ='HOUSE DATA'!B15 -> -34.156733 | C42: =$D$5 -> -0.3 | D42: =2*('HOUSE DATA'!D15*('HOUSE DASHBOARD'!$B$14-42.4)+'HOUSE DATA'!E15*('HOUSE DASHBOARD'!$B$15-54.2)+'HOUSE DATA'!F15*('HOUSE DASHBOARD'!$B$16-85.4)+'HOUSE DATA'!G15*('HOUSE DASHBOARD'!$B$17-60.7)+'HOUSE DATA'!H15*('HOUSE DASHBOARD'!$B$18-53.5))/100 -> 0 | E42: =2*('HOUSE DATA'!I15*('HOUSE DASHBOARD'!$B$21-55.6)+(100-'HOUSE DATA'!I15)*('HOUSE DASHBOARD'!$B$22-44.9))/100 -> 0 | F42: =0 -> 0 | G42: =(D42+E42)/2 -> 0 | H42: ='HOUSE DATA'!C15+C42+G42 -> -34.86 | I42: =IF(V42="D","D",IF(V42="R","R",IF(H42>=0,"D","R"))) -> R | J42: ='HOUSE DATA'!K15 -> R | K42: =IF(I42=J42,"—",J42&" → "&I42) -> — | L42: =IF(V42="D","D — BALLOT LOCK",IF(V42="R","R — BALLOT LOCK",IF(H42>=0,"D+"&TEXT(H42,"0.00"),"R+"&TEXT(-H42,"0.00")))) -> R+34.86 | M42: =COUNTIF($H$31:$H$465,">"&H42)+COUNTIF($H$31:H42,H42) -> 412 | N42: =IF(V42<>"",100,ABS(H42)) -> 34.86 | O42: =COUNTIF($N$31:$N$465,"<"&N42)+COUNTIF($N$31:N42,N42) -> 306 | P42: ='HOUSE DATA'!M15 -> -45.82 | Q42: ='HOUSE DATA'!N15 -> 2024 HOUSE / prior substitute | R42: =H42-P42 -> 10.96 | S42: =B42-P42 -> 11.663267 | T42: =H42-B42 -> -0.70326722 | U42: Contested | W42: Both major parties or other ballot arrangement | X42: Standard model; verify if ballot changes
... A54: ='HOUSE DATA'!A27 -> CA-03 | B54: ='HOUSE DATA'!B27 -> 18.966124 | C54: =$D$5 -> -0.3 | D54: =2*('HOUSE DATA'!D27*('HOUSE DASHBOARD'!$B$14-42.4)+'HOUSE DATA'!E27*('HOUSE DASHBOARD'!$B$15-54.2)+'HOUSE DATA'!F27*('HOUSE DASHBOARD'!$B$16-85.4)+'HOUSE DATA'!G27*('HOUSE DASHBOARD'!$B$17-60.7)+'HOUSE DATA'!H27*('HOUSE DASHBOARD'!$B$18-53.5))/100 -> 0 | E54: =2*('HOUSE DATA'!I27*('HOUSE DASHBOARD'!$B$21-55.6)+(100-'HOUSE DATA'!I27)*('HOUSE DASHBOARD'!$B$22-44.9))/100 -> 0 | F54: =0 -> 0 | G54: =(D54+E54)/2 -> 0 | H54: ='HOUSE DATA'!C27+C54+G54 -> 21.376667 | I54: =IF(V54="D","D",IF(V54="R","R",IF(H54>=0,"D","R"))) -> D | J54: ='HOUSE DATA'!K27 -> R | K54: =IF(I54=J54,"—",J54&" → "&I54) -> R → D | L54: =IF(V54="D","D — BALLOT LOCK",IF(V54="R","R — BALLOT LOCK",IF(H54>=0,"D+"&TEXT(H54,"0.00"),"R+"&TEXT(-H54,"0.00")))) -> D+21.38 | M54: =COUNTIF($H$31:$H$465,">"&H54)+COUNTIF($H$31:H54,H54) -> 162 | N54: =IF(V54<>"",100,ABS(H54)) -> 21.376667 | O54: =COUNTIF($N$31:$N$465,"<"&N54)+COUNTIF($N$31:N54,N54) -> 202 | P54: ='HOUSE DATA'!M27 -> 10.416667 | Q54: ='HOUSE DATA'!N27 -> 2024 HOUSE / prior substitute | R54: =H54-P54 -> 10.96 | S54: =B54-P54 -> 8.5494569 | T54: =H54-B54 -> 2.4105431 | U54: Contested | W54: Both major parties or other ballot arrangement | X54: Standard model; verify if ballot changes
A55: ='HOUSE DATA'!A28 -> CA-04 | B55: ='HOUSE DATA'!B28 -> 26.064555 | C55: =$D$5 -> -0.3 | D55: =2*('HOUSE DATA'!D28*('HOUSE DASHBOARD'!$B$14-42.4)+'HOUSE DATA'!E28*('HOUSE DASHBOARD'!$B$15-54.2)+'HOUSE DATA'!F28*('HOUSE DASHBOARD'!$B$16-85.4)+'HOUSE DATA'!G28*('HOUSE DASHBOARD'!$B$17-60.7)+'HOUSE DATA'!H28*('HOUSE DASHBOARD'!$B$18-53.5))/100 -> 0 | E55: =2*('HOUSE DATA'!I28*('HOUSE DASHBOARD'!$B$21-55.6)+(100-'HOUSE DATA'!I28)*('HOUSE DASHBOARD'!$B$22-44.9))/100 -> 0 | F55: =0 -> 0 | G55: =(D55+E55)/2 -> 0 | H55: ='HOUSE DATA'!C28+C55+G55 -> 26.423918 | I55: =IF(V55="D","D",IF(V55="R","R",IF(H55>=0,"D","R"))) -> D | J55: ='HOUSE DATA'!K28 -> D | K55: =IF(I55=J55,"—",J55&" → "&I55) -> — | L55: =IF(V55="D","D — BALLOT LOCK",IF(V55="R","R — BALLOT LOCK",IF(H55>=0,"D+"&TEXT(H55,"0.00"),"R+"&TEXT(-H55,"0.00")))) -> D — BALLOT LOCK | M55: =COUNTIF($H$31:$H$465,">"&H55)+COUNTIF($H$31:H55,H55) -> 137 | N55: =IF(V55<>"",100,ABS(H55)) -> 100 | O55: =COUNTIF($N$31:$N$465,"<"&N55)+COUNTIF($N$31:N55,N55) -> 422 | P55: ='HOUSE DATA'!M28 -> 15.463918 | Q55: ='HOUSE DATA'!N28 -> 2024 HOUSE / prior substitute | R55: =H55-P55 -> 10.96 | S55: =B55-P55 -> 10.600637 | T55: =H55-B55 -> 0.35936268 | U55: Two Democrats | V55: D | W55: California top-two primary: two Democrats advanced | X55: Ballot lock: both general-election candidates are Democrats
A56: ='HOUSE DATA'!A29 -> CA-05 | B56: ='HOUSE DATA'!B29 -> -11.34087 | C56: =$D$5 -> -0.3 | D56: =2*('HOUSE DATA'!D29*('HOUSE DASHBOARD'!$B$14-42.4)+'HOUSE DATA'!E29*('HOUSE DASHBOARD'!$B$15-54.2)+'HOUSE DATA'!F29*('HOUSE DASHBOARD'!$B$16-85.4)+'HOUSE DATA'!G29*('HOUSE DASHBOARD'!$B$17-60.7)+'HOUSE DATA'!H29*('HOUSE DASHBOARD'!$B$18-53.5))/100 -> 0 | E56: =2*('HOUSE DATA'!I29*('HOUSE DASHBOARD'!$B$21-55.6)+(100-'HOUSE DATA'!I29)*('HOUSE DASHBOARD'!$B$22-44.9))/100 -> 0 | F56: =0 -> 0 | G56: =(D56+E56)/2 -> 0 | H56: ='HOUSE DATA'!C29+C56+G56 -> -10.689485 | I56: =IF(V56="D","D",IF(V56="R","R",IF(H56>=0,"D","R"))) -> R | J56: ='HOUSE DATA'!K29 -> R | K56: =IF(I56=J56,"—",J56&" → "&I56) -> — | L56: =IF(V56="D","D — BALLOT LOCK",IF(V56="R","R — BALLOT LOCK",IF(H56>=0,"D+"&TEXT(H56,"0.00"),"R+"&TEXT(-H56,"0.00")))) -> R+10.69 | M56: =COUNTIF($H$31:$H$465,">"&H56)+COUNTIF($H$31:H56,H56) -> 308 | N56: =IF(V56<>"",100,ABS(H56)) -> 10.689485 | O56: =COUNTIF($N$31:$N$465,"<"&N56)+COUNTIF($N$31:N56,N56) -> 98 | P56: ='HOUSE DATA'!M29 -> -21.649485 | Q56: ='HOUSE DATA'!N29 -> 2024 HOUSE / prior substitute | R56: =H56-P56 -> 10.96 | S56: =B56-P56 -> 10.308615 | T56: =H56-B56 -> 0.65138543 | U56: Contested | W56: Both major parties or other ballot arrangement | X56: Standard model; verify if ballot changes
...

Sheet SENATE DASHBOARD
A1: 2026 ELECTION SIMULATOR / SENATE | 100 SEATS
A2: Linked to House inputs • live seat count and state results below.
A4: NATIONAL ENVIRONMENT | G4: LIVE SEAT COUNT
A5: National generic ballot · D−R | B5: ='HOUSE DASHBOARD'!B5 -> 8.4 | C5: 8.7 | D5: ='HOUSE DASHBOARD'!D5 -> -0.3 | E5: Senate baselines vary by state | G5: Democratic seats | I5: Republican seats
A6: Demographic scenario | B6: All edited groups | E6: Active demographics: RACE + EDUCATION only | G6: =34+COUNTIF(I32:I66,"D") -> 52 | I6: =31+COUNTIF(I32:I66,"R") -> 48
A7: Additional swing (pp) | B7: ='HOUSE DASHBOARD'!B7 -> 0 | E7: 0 = no extra adjustment
A8: Simulated national margin | B8: ='HOUSE DASHBOARD'!B8 -> 8.4 | E8: Implied national vote margin reflects scenario settings.
A9: Scenario | B9: ='HOUSE DASHBOARD'!B9 -> Custom | C9: Preset (generic ballot mode only) | G9: D seat change | H9: =G6-47 -> 5 | I9: R seat change | J9: =-H9 -> -5
A10: Starting baseline | B10: ='HOUSE DASHBOARD'!B10 -> Uniform swing | C10: Each contest has its own 2026 forecast baseline | E10: Uniform swing = pre-demographic forecast (DATA col C); Original forecast = legacy modeled forecast (DATA col B). Neither is raw 2024 result. | G10: 100 Senate seats: 35 contested + 65 not up (34 D / 31 R).
A11: National calculation | B11: ='HOUSE DASHBOARD'!B11 -> Generic ballot | C11: -1.48 | D11: 2024 presidential baseline (D−R pp) | E11: Mode: Generic ballot combines the ballot swing with vote-share changes; Demographic-driven uses vote-share changes alone.
A13: RACE / ETHNICITY | B13: EDIT D % | C13: 2024 National Baseline (R+1.5) | D13: 2020 National Baseline (D+ 4.5) | E13: 2018 National House (D+8.4) | F13: Applied D% | G13: Category switch | I13: 2018 US D% (D+8.4) | J13: Race | K13: 2024 reference % | L13: 2026 entered % | M13: Applied % | N13: Change pp
A14: White (non-Hispanic) | B14: ='HOUSE DASHBOARD'!B14 -> 42.4 | C14: 42.4 | D14: 42 | E14: 45 | F14: ='HOUSE DASHBOARD'!F14 -> 42.4 | G14: Race | H14: ='HOUSE DASHBOARD'!H14 -> 0 | I14: ='HOUSE DASHBOARD'!I14 -> 44 | J14: White non-Hispanic | K14: ='HOUSE DASHBOARD'!K14 -> 75 | L14: ='HOUSE DASHBOARD'!L14 -> 75 | M14: ='HOUSE DASHBOARD'!M14 -> 75 | N14: =M14-K14 -> 0 | O14: Race reset
A15: Hispanic / Latino | B15: ='HOUSE DASHBOARD'!B15 -> 54.2 | C15: 54.2 | D15: 63 | E15: 67 | F15: ='HOUSE DASHBOARD'!F15 -> 54.2 | G15: 2024 baseline = ignore edits | I15: ='HOUSE DASHBOARD'!I15 -> 69 | J15: Hispanic / Latino | K15: ='HOUSE DASHBOARD'!K15 -> 10 | L15: ='HOUSE DASHBOARD'!L15 -> 10 | M15: ='HOUSE DASHBOARD'!M15 -> 10 | N15: =M15-K15 -> 0
A16: Black | B16: ='HOUSE DASHBOARD'!B16 -> 85.4 | C16: 85.4 | D16: 90 | E16: 91 | F16: ='HOUSE DASHBOARD'!F16 -> 85.4 | I16: ='HOUSE DASHBOARD'!I16 -> 90 | J16: Black | K16: ='HOUSE DASHBOARD'!K16 -> 10 | L16: ='HOUSE DASHBOARD'!L16 -> 10 | M16: ='HOUSE DASHBOARD'!M16 -> 10 | N16: =M16-K16 -> 0
A17: Asian | B17: ='HOUSE DASHBOARD'!B17 -> 60.7 | C17: 60.7 | D17: 64 | E17: 62 | F17: ='HOUSE DASHBOARD'!F17 -> 60.7 | I17: ='HOUSE DASHBOARD'!I17 -> 77 | J17: Asian | K17: ='HOUSE DASHBOARD'!K17 -> 2.3011941 | L17: ='HOUSE DASHBOARD'!L17 -> 2.3011941 | M17: ='HOUSE DASHBOARD'!M17 -> 2.3011941 | N17: =M17-K17 -> 0
A18: Other / unclassified | B18: ='HOUSE DASHBOARD'!B18 -> 53.5 | C18: 53.5 | F18: ='HOUSE DASHBOARD'!F18 -> 53.5 | J18: Other / unclassified | K18: ='HOUSE DASHBOARD'!K18 -> 2.6988059 | L18: ='HOUSE DASHBOARD'!L18 -> 2.6988059 | M18: ='HOUSE DASHBOARD'!M18 -> 2.6988059 | N18: =M18-K18 -> 0
A20: EDUCATION GROUP | B20: EDIT D % | C20: 2024 National Baseline (R+1.5) | D20: 2020 National Baseline (D+ 4.5) | E20: 2018 National House (D+8.4) | F20: Applied D% | J20: Education | K20: 2024 electorate % | L20: 2026 entered % | M20: Applied % | N20: Change pp
A21: College degree (BA+) | B21: ='HOUSE DASHBOARD'!B21 -> 55.6 | C21: 55.6 | D21: 56 | E21: 57 | F21: ='HOUSE DASHBOARD'!F21 -> 55.6 | G21: Education | H21: ='HOUSE DASHBOARD'!H21 -> 0 | J21: College degree (BA+) | K21: ='HOUSE DASHBOARD'!K21 -> 42 | L21: ='HOUSE DASHBOARD'!L21 -> 42 | M21: ='HOUSE DASHBOARD'!M21 -> 42 | N21: =M21-K21 -> 0 | O21: Education reset
A22: Without BA degree | B22: ='HOUSE DASHBOARD'!B22 -> 44.9 | C22: 44.9 | D22: 49 | E22: 52 | F22: ='HOUSE DASHBOARD'!F22 -> 44.9 | J22: No BA degree | K22: ='HOUSE DASHBOARD'!K22 -> 58 | L22: ='HOUSE DASHBOARD'!L22 -> 58 | M22: ='HOUSE DASHBOARD'!M22 -> 58 | N22: =M22-K22 -> 0
J23: 2024 education: 42% BA+ / 58% no BA (provided exit-poll screenshot).
J24: 2024 race/income composition from exit poll; Asian/Other split is estimated.
J25: Income composition is editable in House Dashboard S18:S20.
G26: Catalist 2024 voter analysis | H26: https://catalist.us/whathappened2024/ | J26: Race entries normalize to 100%; education and income complements auto-fill.
G27: 2025 Virginia exit poll | H27: https://en.wikipedia.org/wiki/2025_Virginia_gubernatorial_election#Exit_poll | J27: National and district effects centered; race/education/income weighted 1/3 each.
J28: Exploratory sensitivity model, not a validated electorate or seat forecast.
A29: State results
A30: Tipping-point race (D seat #51) | B30: =LARGE(H32:H66,17) -> 2.7917647 | D30: Tipping contest | E30: =INDEX(A32:A66,MATCH(17,M32:M66,0)) -> Maine | G30: D seats needed | H30: =MAX(0,51-G6) -> 0 | I30: R seats needed | J30: =MAX(0,51-I6) -> 3
A31: District / state | B31: Original D−R | C31: National Δ | D31: Race Δ | E31: Education Δ | F31: Income (excluded) | G31: Race + Education Δ | H31: SCENARIO D−R | I31: Party | J31: Baseline holder / reference | K31: Flip vs reference | L31: Display margin | M31: D margin rank | N31: Absolute margin | O31: Closeness rank | P31: Source baseline D−R | Q31: Source election / proxy | R31: Scenario − historical | S31: Legacy forecast − baseline | T31: Scenario − legacy forecast
A32: ='SENATE DATA'!A4 -> Alabama | B32: ='SENATE DATA'!B4 -> -20.096479 | C32: =$D$5 -> -0.3 | D32: =2*('SENATE DATA'!D4*('HOUSE DASHBOARD'!$B$14-42.4)+'SENATE DATA'!E4*('HOUSE DASHBOARD'!$B$15-54.2)+'SENATE DATA'!F4*('HOUSE DASHBOARD'!$B$16-85.4)+'SENATE DATA'!G4*('HOUSE DASHBOARD'!$B$17-60.7)+'SENATE DATA'!H4*('HOUSE DASHBOARD'!$B$18-53.5))/100 -> 0 | E32: =2*('SENATE DATA'!I4*('HOUSE DASHBOARD'!$B$21-55.6)+(100-'SENATE DATA'!I4)*('HOUSE DASHBOARD'!$B$22-44.9))/100 -> 0 | F32: =0 -> 0 | G32: =(D32+E32)/2 -> 0 | H32: ='SENATE DATA'!C4+C32+G32 -> -20.6 | I32: =IF(H32>=0,"D","R") -> R | J32: ='SENATE DATA'!K4 -> R | K32: =IF(I32=J32,"—",J32&" → "&I32) -> — | L32: =IF(H32>=0,"D+"&TEXT(H32,"0.00"),"R+"&TEXT(-H32,"0.00")) -> R+20.60 | M32: =COUNTIF($H$32:$H$66,">"&H32)+COUNTIF($H$32:H32,H32) -> 29 | N32: =ABS(H32) -> 20.6 | O32: =COUNTIF($N$32:$N$66,"<"&N32)+COUNTIF($N$32:N32,N32) -> 25 | P32: ='SENATE DATA'!M4 -> -30.47 | Q32: ='SENATE DATA'!N4 -> 2024 PRESIDENTIAL | R32: =H32-P32 -> 9.87 | S32: =B32-P32 -> 10.373521 | T32: =H32-B32 -> -0.50352115
A33: ='SENATE DATA'!A5 -> Alaska | B33: ='SENATE DATA'!B5 -> -0.37847584 | C33: =$D$5 -> -0.3 | D33: =2*('SENATE DATA'!D5*('HOUSE DASHBOARD'!$B$14-42.4)+'SENATE DATA'!E5*('HOUSE DASHBOARD'!$B$15-54.2)+'SENATE DATA'!F5*('HOUSE DASHBOARD'!$B$16-85.4)+'SENATE DATA'!G5*('HOUSE DASHBOARD'!$B$17-60.7)+'SENATE DATA'!H5*('HOUSE DASHBOARD'!$B$18-53.5))/100 -> 0 | E33: =2*('SENATE DATA'!I5*('HOUSE DASHBOARD'!$B$21-55.6)+(100-'SENATE DATA'!I5)*('HOUSE DASHBOARD'!$B$22-44.9))/100 -> 0 | F33: =0 -> 0 | G33: =(D33+E33)/2 -> 0 | H33: ='SENATE DATA'!C5+C33+G33 -> 1 | I33: =IF(H33>=0,"D","R") -> D | J33: ='SENATE DATA'!K5 -> R | K33: =IF(I33=J33,"—",J33&" → "&I33) -> R → D | L33: =IF(H33>=0,"D+"&TEXT(H33,"0.00"),"R+"&TEXT(-H33,"0.00")) -> D+1.00 | M33: =COUNTIF($H$32:$H$66,">"&H33)+COUNTIF($H$32:H33,H33) -> 18 | N33: =ABS(H33) -> 1 | O33: =COUNTIF($N$32:$N$66,"<"&N33)+COUNTIF($N$32:N33,N33) -> 1 | P33: ='SENATE DATA'!M5 -> 1.3 | Q33: ='SENATE DATA'!N5 -> 2020 PRES + 2024 HOUSE (50/50) | R33: =H33-P33 -> -0.3 | S33: =B33-P33 -> -1.6784758 | T33: =H33-B33 -> 1.3784758
A34: ='SENATE DATA'!A6 -> Arkansas | B34: ='SENATE DATA'!B6 -> -20.222228 | C34: =$D$5 -> -0.3 | D34: =2*('SENATE DATA'!D6*('HOUSE DASHBOARD'!$B$14-42.4)+'SENATE DATA'!E6*('HOUSE DASHBOARD'!$B$15-54.2)+'SENATE DATA'!F6*('HOUSE DASHBOARD'!$B$16-85.4)+'SENATE DATA'!G6*('HOUSE DASHBOARD'!$B$17-60.7)+'SENATE DATA'!H6*('HOUSE DASHBOARD'!$B$18-53.5))/100 -> 0 | E34: =2*('SENATE DATA'!I6*('HOUSE DASHBOARD'!$B$21-55.6)+(100-'SENATE DATA'!I6)*('HOUSE DASHBOARD'!$B$22-44.9))/100 -> 0 | F34: =0 -> 0 | G34: =(D34+E34)/2 -> 0 | H34: ='SENATE DATA'!C6+C34+G34 -> -20.77 | I34: =IF(H34>=0,"D","R") -> R | J34: ='SENATE DATA'!K6 -> R | K34: =IF(I34=J34,"—",J34&" → "&I34) -> — | L34: =IF(H34>=0,"D+"&TEXT(H34,"0.00"),"R+"&TEXT(-H34,"0.00")) -> R+20.77 | M34: =COUNTIF($H$32:$H$66,">"&H34)+COUNTIF($H$32:H34,H34) -> 31 | N34: =ABS(H34) -> 20.77 | O34: =COUNTIF($N$32:$N$66,"<"&N34)+COUNTIF($N$32:N34,N34) -> 27 | P34: ='SENATE DATA'!M6 -> -30.64 | Q34: ='SENATE DATA'!N6 -> 2024 PRESIDENTIAL | R34: =H34-P34 -> 9.87 | S34: =B34-P34 -> 10.417772 | T34: =H34-B34 -> -0.54777166
A35: ='SENATE DATA'!A7 -> Colorado | B35: ='SENATE DATA'!B7 -> 11.952218 | C35: =$D$5 -> -0.3 | D35: =2*('SENATE DATA'!D7*('HOUSE DASHBOARD'!$B$14-42.4)+'SENATE DATA'!E7*('HOUSE DASHBOARD'!$B$15-54.2)+'SENATE DATA'!F7*('HOUSE DASHBOARD'!$B$16-85.4)+'SENATE DATA'!G7*('HOUSE DASHBOARD'!$B$17-60.7)+'SENATE DATA'!H7*('HOUSE DASHBOARD'!$B$18-53.5))/100 -> 0 | E35: =2*('SENATE DATA'!I7*('HOUSE DASHBOARD'!$B$21-55.6)+(100-'SENATE DATA'!I7)*('HOUSE DASHBOARD'!$B$22-44.9))/100 -> 0 | F35: =0 -> 0 | G35: =(D35+E35)/2 -> 0 | H35: ='SENATE DATA'!C7+C35+G35 -> 13.25 | I35: =IF(H35>=0,"D","R") -> D | J35: ='SENATE DATA'!K7 -> D | K35: =IF(I35=J35,"—",J35&" → "&I35) -> — | L35: =IF(H35>=0,"D+"&TEXT(H35,"0.00"),"R+"&TEXT(-H35,"0.00")) -> D+13.25 | M35: =COUNTIF($H$32:$H$66,">"&H35)+COUNTIF($H$32:H35,H35) -> 9 | N35: =ABS(H35) -> 13.25 | O35: =COUNTIF($N$32:$N$66,"<"&N35)+COUNTIF($N$32:N35,N35) -> 19 | P35: ='SENATE DATA'!M7 -> 9.3 | Q35: ='SENATE DATA'!N7 -> 2020 SENATE | R35: =H35-P35 -> 3.95 | S35: =B35-P35 -> 2.6522175 | T35: =H35-B35 -> 1.2977825
A36: ='SENATE DATA'!A8 -> Delaware | B36: ='SENATE DATA'!B8 -> 24.645629 | C36: =$D$5 -> -0.3 | D36: =2*('SENATE DATA'!D8*('HOUSE DASHBOARD'!$B$14-42.4)+'SENATE DATA'!E8*('HOUSE DASHBOARD'!$B$15-54.2)+'SENATE DATA'!F8*('HOUSE DASHBOARD'!$B$16-85.4)+'SENATE DATA'!G8*('HOUSE DASHBOARD'!$B$17-60.7)+'SENATE DATA'!H8*('HOUSE DASHBOARD'!$B$18-53.5))/100 -> 0 | E36: =2*('SENATE DATA'!I8*('HOUSE DASHBOARD'!$B$21-55.6)+(100-'SENATE DATA'!I8)*('HOUSE DASHBOARD'!$B$22-44.9))/100 -> 0 | F36: =0 -> 0 | G36: =(D36+E36)/2 -> 0 | H36: ='SENATE DATA'!C8+C36+G36 -> 25.45 | I36: =IF(H36>=0,"D","R") -> D | J36: ='SENATE DATA'!K8 -> D | K36: =IF(I36=J36,"—",J36&" → "&I36) -> — | L36: =IF(H36>=0,"D+"&TEXT(H36,"0.00"),"R+"&TEXT(-H36,"0.00")) -> D+25.45 | M36: =COUNTIF($H$32:$H$66,">"&H36)+COUNTIF($H$32:H36,H36) -> 3 | N36: =ABS(H36) -> 25.45 | O36: =COUNTIF($N$32:$N$66,"<"&N36)+COUNTIF($N$32:N36,N36) -> 31 | P36: ='SENATE DATA'!M8 -> 21.5 | Q36: ='SENATE DATA'!N8 -> 2020 SENATE | R36: =H36-P36 -> 3.95 | S36: =B36-P36 -> 3.1456286 | T36: =H36-B36 -> 0.80437142
A37: ='SENATE DATA'!A9 -> Florida | B37: ='SENATE DATA'!B9 -> -2.0662831 | C37: =$D$5 -> -0.3 | D37: =2*('SENATE DATA'!D9*('HOUSE DASHBOARD'!$B$14-42.4)+'SENATE DATA'!E9*('HOUSE DASHBOARD'!$B$15-54.2)+'SENATE DATA'!F9*('HOUSE DASHBOARD'!$B$16-85.4)+'SENATE DATA'!G9*('HOUSE DASHBOARD'!$B$17-60.7)+'SENATE DATA'!H9*('HOUSE DASHBOARD'!$B$18-53.5))/100 -> 0 | E37: =2*('SENATE DATA'!I9*('HOUSE DASHBOARD'!$B$21-55.6)+(100-'SENATE DATA'!I9)*('HOUSE DASHBOARD'!$B$22-44.9))/100 -> 0 | F37: =0 -> 0 | G37: =(D37+E37)/2 -> 0 | H37: ='SENATE DATA'!C9+C37+G37 -> -3.23 | I37: =IF(H37>=0,"D","R") -> R | J37: ='SENATE DATA'!K9 -> R | K37: =IF(I37=J37,"—",J37&" → "&I37) -> — | L37: =IF(H37>=0,"D+"&TEXT(H37,"0.00"),"R+"&TEXT(-H37,"0.00")) -> R+3.23 | M37: =COUNTIF($H$32:$H$66,">"&H37)+COUNTIF($H$32:H37,H37) -> 19 | N37: =ABS(H37) -> 3.23 | O37: =COUNTIF($N$32:$N$66,"<"&N37)+COUNTIF($N$32:N37,N37) -> 4 | P37: ='SENATE DATA'!M9 -> -13.1 | Q37: ='SENATE DATA'!N9 -> 2024 PRESIDENTIAL | R37: =H37-P37 -> 9.87 | S37: =B37-P37 -> 11.033717 | T37: =H37-B37 -> -1.1637169
A38: ='SENATE DATA'!A10 -> Georgia | B38: ='SENATE DATA'!B10 -> 5.5586341 | C38: =$D$5 -> -0.3 | D38: =2*('SENATE DATA'!D10*('HOUSE DASHBOARD'!$B$14-42.4)+'SENATE DATA'!E10*('HOUSE DASHBOARD'!$B$15-54.2)+'SENATE DATA'!F10*('HOUSE DASHBOARD'!$B$16-85.4)+'SENATE DATA'!G10*('HOUSE DASHBOARD'!$B$17-60.7)+'SENATE DATA'!H10*('HOUSE DASHBOARD'!$B$18-53.5))/100 -> 0 | E38: =2*('SENATE DATA'!I10*('HOUSE DASHBOARD'!$B$21-55.6)+(100-'SENATE DATA'!I10)*('HOUSE DASHBOARD'!$B$22-44.9))/100 -> 0 | F38: =0 -> 0 | G38: =(D38+E38)/2 -> 0 | H38: ='SENATE DATA'!C10+C38+G38 -> 5.1751 | I38: =IF(H38>=0,"D","R") -> D | J38: ='SENATE DATA'!K10 -> D | K38: =IF(I38=J38,"—",J38&" → "&I38) -> — | L38: =IF(H38>=0,"D+"&TEXT(H38,"0.00"),"R+"&TEXT(-H38,"0.00")) -> D+5.18 | M38: =COUNTIF($H$32:$H$66,">"&H38)+COUNTIF($H$32:H38,H38) -> 15 | N38: =ABS(H38) -> 5.1751 | O38: =COUNTIF($N$32:$N$66,"<"&N38)+COUNTIF($N$32:N38,N38) -> 7 | P38: ='SENATE DATA'!M10 -> 1.2251 | Q38: ='SENATE DATA'!N10 -> 2021 SENATE RUNOFF | R38: =H38-P38 -> 3.95 | S38: =B38-P38 -> 4.3335341 | T38: =H38-B38 -> -0.38353409
A39: ='SENATE DATA'!A11 -> Idaho | B39: ='SENATE DATA'!B11 -> -25.15 | C39: =$D$5 -> -0.3 | D39: =2*('SENATE DATA'!D11*('HOUSE DASHBOARD'!$B$14-42.4)+'SENATE DATA'!E11*('HOUSE DASHBOARD'!$B$15-54.2)+'SENATE DATA'!F11*('HOUSE DASHBOARD'!$B$16-85.4)+'SENATE DATA'!G11*('HOUSE DASHBOARD'!$B$17-60.7)+'SENATE DATA'!H11*('HOUSE DASHBOARD'!$B$18-53.5))/100 -> 0 | E39: =2*('SENATE DATA'!I11*('HOUSE DASHBOARD'!$B$21-55.6)+(100-'SENATE DATA'!I11)*('HOUSE DASHBOARD'!$B$22-44.9))/100 -> 0 | F39: =0 -> 0 | G39: =(D39+E39)/2 -> 0 | H39: ='SENATE DATA'!C11+C39+G39+'SENATE DATA'!$P$3 -> -11.55 | I39: =IF(H39>=0,"D","R") -> R | J39: ='SENATE DATA'!K11 -> R | K39: =IF(I39=J39,"—",J39&" → "&I39) -> — | L39: =IF(H39>=0,"D+"&TEXT(H39,"0.00"),"R+"&TEXT(-H39,"0.00")) -> R+11.55 | M39: =COUNTIF($H$32:$H$66,">"&H39)+COUNTIF($H$32:H39,H39) -> 26 | N39: =ABS(H39) -> 11.55 | O39: =COUNTIF($N$32:$N$66,"<"&N39)+COUNTIF($N$32:N39,N39) -> 16 | P39: ='SENATE DATA'!M11 -> -29.4 | Q39: ='SENATE DATA'!N11 -> 2020 SENATE | R39: =H39-P39 -> 17.85 | S39: =B39-P39 -> 4.25 | T39: =H39-B39 -> 13.6
A40: ='SENATE DATA'!A12 -> Illinois | B40: ='SENATE DATA'!B12 -> 20.786307 | C40: =$D$5 -> -0.3 | D40: =2*('SENATE DATA'!D12*('HOUSE DASHBOARD'!$B$14-42.4)+'SENATE DATA'!E12*('HOUSE DASHBOARD'!$B$15-54.2)+'SENATE DATA'!F12*('HOUSE DASHBOARD'!$B$16-85.4)+'SENATE DATA'!G12*('HOUSE DASHBOARD'!$B$17-60.7)+'SENATE DATA'!H12*('HOUSE DASHBOARD'!$B$18-53.5))/100 -> 0 | E40: =2*('SENATE DATA'!I12*('HOUSE DASHBOARD'!$B$21-55.6)+(100-'SENATE DATA'!I12)*('HOUSE DASHBOARD'!$B$22-44.9))/100 -> 0 | F40: =0 -> 0 | G40: =(D40+E40)/2 -> 0 | H40: ='SENATE DATA'!C12+C40+G40 -> 20.77 | I40: =IF(H40>=0,"D","R") -> D | J40: ='SENATE DATA'!K12 -> D | K40: =IF(I40=J40,"—",J40&" → "&I40) -> — | L40: =IF(H40>=0,"D+"&TEXT(H40,"0.00"),"R+"&TEXT(-H40,"0.00")) -> D+20.77 | M40: =COUNTIF($H$32:$H$66,">"&H40)+COUNTIF($H$32:H40,H40) -> 4 | N40: =ABS(H40) -> 20.77 | O40: =COUNTIF($N$32:$N$66,"<"&N40)+COUNTIF($N$32:N40,N40) -> 28 | P40: ='SENATE DATA'!M12 -> 10.9 | Q40: ='SENATE DATA'!N12 -> 2024 PRESIDENTIAL | R40: =H40-P40 -> 9.87 | S40: =B40-P40 -> 9.8863068 | T40: =H40-B40 -> -0.016306849
A41: ='SENATE DATA'!A13 -> Iowa | B41: ='SENATE DATA'!B13 -> -4.2738161 | C41: =$D$5 -> -0.3 | D41: =2*('SENATE DATA'!D13*('HOUSE DASHBOARD'!$B$14-42.4)+'SENATE DATA'!E13*('HOUSE DASHBOARD'!$B$15-54.2)+'SENATE DATA'!F13*('HOUSE DASHBOARD'!$B$16-85.4)+'SENATE DATA'!G13*('HOUSE DASHBOARD'!$B$17-60.7)+'SENATE DATA'!H13*('HOUSE DASHBOARD'!$B$18-53.5))/100 -> 0 | E41: =2*('SENATE DATA'!I13*('HOUSE DASHBOARD'!$B$21-55.6)+(100-'SENATE DATA'!I13)*('HOUSE DASHBOARD'!$B$22-44.9))/100 -> 0 | F41: =0 -> 0 | G41: =(D41+E41)/2 -> 0 | H41: ='SENATE DATA'!C13+C41+G41 -> -3.34 | I41: =IF(H41>=0,"D","R") -> R | J41: ='SENATE DATA'!K13 -> R | K41: =IF(I41=J41,"—",J41&" → "&I41) -> — | L41: =IF(H41>=0,"D+"&TEXT(H41,"0.00"),"R+"&TEXT(-H41,"0.00")) -> R+3.34 | M41: =COUNTIF($H$32:$H$66,">"&H41)+COUNTIF($H$32:H41,H41) -> 20 | N41: =ABS(H41) -> 3.34 | O41: =COUNTIF($N$32:$N$66,"<"&N41)+COUNTIF($N$32:N41,N41) -> 5 | P41: ='SENATE DATA'!M13 -> -13.21 | Q41: ='SENATE DATA'!N13 -> 2024 PRESIDENTIAL | R41: =H41-P41 -> 9.87 | S41: =B41-P41 -> 8.9361839 | T41: =H41-B41 -> 0.93381613
A42: ='SENATE DATA'!A14 -> Kansas | B42: ='SENATE DATA'!B14 -> -7.9011664 | C42: =$D$5 -> -0.3 | D42: =2*('SENATE DATA'!D14*('HOUSE DASHBOARD'!$B$14-42.4)+'SENATE DATA'!E14*('HOUSE DASHBOARD'!$B$15-54.2)+'SENATE DATA'!F14*('HOUSE DASHBOARD'!$B$16-85.4)+'SENATE DATA'!G14*('HOUSE DASHBOARD'!$B$17-60.7)+'SENATE DATA'!H14*('HOUSE DASHBOARD'!$B$18-53.5))/100 -> 0 | E42: =2*('SENATE DATA'!I14*('HOUSE DASHBOARD'!$B$21-55.6)+(100-'SENATE DATA'!I14)*('HOUSE DASHBOARD'!$B$22-44.9))/100 -> 0 | F42: =0 -> 0 | G42: =(D42+E42)/2 -> 0 | H42: ='SENATE DATA'!C14+C42+G42 -> -7.45 | I42: =IF(H42>=0,"D","R") -> R | J42: ='SENATE DATA'!K14 -> R | K42: =IF(I42=J42,"—",J42&" → "&I42) -> — | L42: =IF(H42>=0,"D+"&TEXT(H42,"0.00"),"R+"&TEXT(-H42,"0.00")) -> R+7.45 | M42: =COUNTIF($H$32:$H$66,">"&H42)+COUNTIF($H$32:H42,H42) -> 23 | N42: =ABS(H42) -> 7.45 | O42: =COUNTIF($N$32:$N$66,"<"&N42)+COUNTIF($N$32:N42,N42) -> 11 | P42: ='SENATE DATA'!M14 -> -11.4 | Q42: ='SENATE DATA'!N14 -> 2020 SENATE | R42: =H42-P42 -> 3.95 | S42: =B42-P42 -> 3.4988336 | T42: =H42-B42 -> 0.45116635
A43: ='SENATE DATA'!A15 -> Kentucky | B43: ='SENATE DATA'!B15 -> -20.951572 | C43: =$D$5 -> -0.3 | D43: =2*('SENATE DATA'!D15*('HOUSE DASHBOARD'!$B$14-42.4)+'SENATE DATA'!E15*('HOUSE DASHBOARD'!$B$15-54.2)+'SENATE DATA'!F15*('HOUSE DASHBOARD'!$B$16-85.4)+'SENATE DATA'!G15*('HOUSE DASHBOARD'!$B$17-60.7)+'SENATE DATA'!H15*('HOUSE DASHBOARD'!$B$18-53.5))/100 -> 0 | E43: =2*('SENATE DATA'!I15*('HOUSE DASHBOARD'!$B$21-55.6)+(100-'SENATE DATA'!I15)*('HOUSE DASHBOARD'!$B$22-44.9))/100 -> 0 | F43: =0 -> 0 | G43: =(D43+E43)/2 -> 0 | H43: ='SENATE DATA'!C15+C43+G43 -> -20.66 | I43: =IF(H43>=0,"D","R") -> R | J43: ='SENATE DATA'!K15 -> R | K43: =IF(I43=J43,"—",J43&" → "&I43) -> — | L43: =IF(H43>=0,"D+"&TEXT(H43,"0.00"),"R+"&TEXT(-H43,"0.00")) -> R+20.66 | M43: =COUNTIF($H$32:$H$66,">"&H43)+COUNTIF($H$32:H43,H43) -> 30 | N43: =ABS(H43) -> 20.66 | O43: =COUNTIF($N$32:$N$66,"<"&N43)+COUNTIF($N$32:N43,N43) -> 26 | P43: ='SENATE DATA'!M15 -> -30.53 | Q43: ='SENATE DATA'!N15 -> 2024 PRESIDENTIAL | R43: =H43-P43 -> 9.87 | S43: =B43-P43 -> 9.5784283 | T43: =H43-B43 -> 0.29157168
...

Sheet GOVERNOR DASHBOARD
A1: 2026 ELECTION SIMULATOR / GOVERNORS | 36 CONTESTS
A2: Linked to House inputs • live seat count and state results below.
A4: NATIONAL ENVIRONMENT | G4: LIVE SEAT COUNT
A5: National generic ballot · D−R | B5: ='HOUSE DASHBOARD'!B5 -> 8.4 | C5: 8.7 | D5: ='HOUSE DASHBOARD'!D5 -> -0.3 | E5: Governor baselines vary by state | G5: Democratic seats | I5: Republican seats
A6: Demographic scenario | B6: All edited groups | E6: Active demographics: RACE + EDUCATION only | G6: =COUNTIF(I36:I71,"D")+COUNTIF('GOVERNOR DATA'!Q4:Q17,"D") -> 27 | I6: =COUNTIF(I36:I71,"R")+COUNTIF('GOVERNOR DATA'!Q4:Q17,"R") -> 23
A7: Additional swing (pp) | B7: ='HOUSE DASHBOARD'!B7 -> 0 | E7: 0 = no extra adjustment
A8: Simulated national margin | B8: ='HOUSE DASHBOARD'!B8 -> 8.4 | E8: Implied national vote margin reflects scenario settings.
A9: Scenario | B9: ='HOUSE DASHBOARD'!B9 -> Custom | C9: Preset (generic ballot mode only) | G9: D seat change | H9: =G6-24 -> 3 | I9: R seat change | J9: =-H9 -> -3
A10: Starting baseline | B10: ='HOUSE DASHBOARD'!B10 -> Uniform swing | C10: Each contest has its own 2026 forecast baseline | E10: Uniform swing = pre-demographic forecast (DATA col C); Original forecast = legacy modeled forecast (DATA col B). Neither is raw 2024 result. | G10: 50-state governorship count: 36 simulated elections + 14 fixed off-cycle states.
A11: National calculation | B11: ='HOUSE DASHBOARD'!B11 -> Generic ballot | C11: -1.48 | D11: 2024 presidential baseline (D−R pp) | E11: Mode: Generic ballot combines the ballot swing with vote-share changes; Demographic-driven uses vote-share changes alone. | G11: Off-cycle states stay with their currently elected party; see GOVERNOR DATA.
A13: RACE / ETHNICITY | B13: EDIT D % | C13: 2024 National Baseline (R+1.5) | D13: 2020 National Baseline (D+ 4.5) | E13: 2018 National House (D+8.4) | F13: Applied D% | G13: Category switch
A14: White (non-Hispanic) | B14: ='HOUSE DASHBOARD'!B14 -> 42.4 | C14: 42.4 | D14: 42 | E14: 45 | F14: ='HOUSE DASHBOARD'!F14 -> 42.4 | G14: Race
A15: Hispanic / Latino | B15: ='HOUSE DASHBOARD'!B15 -> 54.2 | C15: 54.2 | D15: 63 | E15: 67 | F15: ='HOUSE DASHBOARD'!F15 -> 54.2 | G15: 2024 baseline = ignore edits
A16: Black | B16: ='HOUSE DASHBOARD'!B16 -> 85.4 | C16: 85.4 | D16: 90 | E16: 91 | F16: ='HOUSE DASHBOARD'!F16 -> 85.4
A17: Asian | B17: ='HOUSE DASHBOARD'!B17 -> 60.7 | C17: 60.7 | D17: 64 | E17: 62 | F17: ='HOUSE DASHBOARD'!F17 -> 60.7
A18: Other / unclassified | B18: ='HOUSE DASHBOARD'!B18 -> 53.5 | C18: 53.5 | F18: ='HOUSE DASHBOARD'!F18 -> 53.5
A20: EDUCATION GROUP | B20: EDIT D % | C20: 2024 National Baseline (R+1.5) | D20: 2020 National Baseline (D+ 4.5) | E20: 2018 National House (D+8.4) | F20: Applied D%
A21: College degree (BA+) | B21: ='HOUSE DASHBOARD'!B21 -> 55.6 | C21: 55.6 | D21: 56 | E21: 57 | F21: ='HOUSE DASHBOARD'!F21 -> 55.6 | G21: Education
A22: Without BA degree | B22: ='HOUSE DASHBOARD'!B22 -> 44.9 | C22: 44.9 | D22: 49 | E22: 52 | F22: ='HOUSE DASHBOARD'!F22 -> 44.9
J27: Exploratory sensitivity model, not a validated electorate or seat forecast.
A28: State results
A30: Closest governor contest (absolute pp) | B30: =SMALL(N36:N71,1) -> 0.3 | D30: Closest state | E30: =INDEX(A36:A71,MATCH(1,O36:O71,0)) -> Texas | G30: D projected wins | H30: =G6 -> 27 | I30: R projected wins | J30: =I6 -> 23
A32: 2026 interactive scenario • historical baseline fixed • teal cells are controls
A35: District / state | B35: Original D−R | C35: National Δ | D35: Race Δ | E35: Education Δ | F35: Income (excluded) | G35: Race + Education Δ | H35: SCENARIO D−R | I35: Party | J35: Baseline holder / reference | K35: Flip vs reference | L35: Display margin | M35: D margin rank | N35: Absolute margin | O35: Closeness rank | P35: Source baseline D−R | Q35: Source election / proxy | R35: Scenario − historical | S35: Legacy forecast − baseline | T35: Scenario − legacy forecast
A36: ='GOVERNOR DATA'!A4 -> Alabama | B36: ='GOVERNOR DATA'!B4 -> -20.116479 | C36: =$D$5 -> -0.3 | D36: =2*('GOVERNOR DATA'!D4*('HOUSE DASHBOARD'!$B$14-42.4)+'GOVERNOR DATA'!E4*('HOUSE DASHBOARD'!$B$15-54.2)+'GOVERNOR DATA'!F4*('HOUSE DASHBOARD'!$B$16-85.4)+'GOVERNOR DATA'!G4*('HOUSE DASHBOARD'!$B$17-60.7)+'GOVERNOR DATA'!H4*('HOUSE DASHBOARD'!$B$18-53.5))/100 -> 0 | E36: =2*('GOVERNOR DATA'!I4*('HOUSE DASHBOARD'!$B$21-55.6)+(100-'GOVERNOR DATA'!I4)*('HOUSE DASHBOARD'!$B$22-44.9))/100 -> 0 | F36: =0 -> 0 | G36: =(D36+E36)/2 -> 0 | H36: ='GOVERNOR DATA'!C4+C36+G36 -> -20.62 | I36: =IF(H36>=0,"D","R") -> R | J36: ='GOVERNOR DATA'!K4 -> R | K36: =IF(I36=J36,"—",J36&" → "&I36) -> — | L36: =IF(H36>=0,"D+"&TEXT(H36,"0.00"),"R+"&TEXT(-H36,"0.00")) -> R+20.62 | M36: =COUNTIF($H$36:$H$71,">"&H36)+COUNTIF($H$36:H36,H36) -> 32 | N36: =ABS(H36) -> 20.62 | O36: =COUNTIF($N$36:$N$71,"<"&N36)+COUNTIF($N$36:N36,N36) -> 23 | P36: ='GOVERNOR DATA'!M4 -> -30.5 | Q36: ='GOVERNOR DATA'!N4 -> 2024 President (2024) | R36: =H36-P36 -> 9.88 | S36: =B36-P36 -> 10.383521 | T36: =H36-B36 -> -0.50352115
A37: ='GOVERNOR DATA'!A5 -> Alaska | B37: ='GOVERNOR DATA'!B5 -> -4.5984758 | C37: =$D$5 -> -0.3 | D37: =2*('GOVERNOR DATA'!D5*('HOUSE DASHBOARD'!$B$14-42.4)+'GOVERNOR DATA'!E5*('HOUSE DASHBOARD'!$B$15-54.2)+'GOVERNOR DATA'!F5*('HOUSE DASHBOARD'!$B$16-85.4)+'GOVERNOR DATA'!G5*('HOUSE DASHBOARD'!$B$17-60.7)+'GOVERNOR DATA'!H5*('HOUSE DASHBOARD'!$B$18-53.5))/100 -> 0 | E37: =2*('GOVERNOR DATA'!I5*('HOUSE DASHBOARD'!$B$21-55.6)+(100-'GOVERNOR DATA'!I5)*('HOUSE DASHBOARD'!$B$22-44.9))/100 -> 0 | F37: =0 -> 0 | G37: =(D37+E37)/2 -> 0 | H37: ='GOVERNOR DATA'!C5+C37+G37 -> -3.22 | I37: =IF(H37>=0,"D","R") -> R | J37: ='GOVERNOR DATA'!K5 -> R | K37: =IF(I37=J37,"—",J37&" → "&I37) -> — | L37: =IF(H37>=0,"D+"&TEXT(H37,"0.00"),"R+"&TEXT(-H37,"0.00")) -> R+3.22 | M37: =COUNTIF($H$36:$H$71,">"&H37)+COUNTIF($H$36:H37,H37) -> 23 | N37: =ABS(H37) -> 3.22 | O37: =COUNTIF($N$36:$N$71,"<"&N37)+COUNTIF($N$36:N37,N37) -> 4 | P37: ='GOVERNOR DATA'!M5 -> -13.1 | Q37: ='GOVERNOR DATA'!N5 -> 2024 President (2024) | R37: =H37-P37 -> 9.88 | S37: =B37-P37 -> 8.5015242 | T37: =H37-B37 -> 1.3784758
A38: ='GOVERNOR DATA'!A6 -> Arizona | B38: ='GOVERNOR DATA'!B6 -> 12.649439 | C38: =$D$5 -> -0.3 | D38: =2*('GOVERNOR DATA'!D6*('HOUSE DASHBOARD'!$B$14-42.4)+'GOVERNOR DATA'!E6*('HOUSE DASHBOARD'!$B$15-54.2)+'GOVERNOR DATA'!F6*('HOUSE DASHBOARD'!$B$16-85.4)+'GOVERNOR DATA'!G6*('HOUSE DASHBOARD'!$B$17-60.7)+'GOVERNOR DATA'!H6*('HOUSE DASHBOARD'!$B$18-53.5))/100 -> 0 | E38: =2*('GOVERNOR DATA'!I6*('HOUSE DASHBOARD'!$B$21-55.6)+(100-'GOVERNOR DATA'!I6)*('HOUSE DASHBOARD'!$B$22-44.9))/100 -> 0 | F38: =0 -> 0 | G38: =(D38+E38)/2 -> 0 | H38: ='GOVERNOR DATA'!C6+C38+G38 -> 11.87 | I38: =IF(H38>=0,"D","R") -> D | J38: ='GOVERNOR DATA'!K6 -> D | K38: =IF(I38=J38,"—",J38&" → "&I38) -> — | L38: =IF(H38>=0,"D+"&TEXT(H38,"0.00"),"R+"&TEXT(-H38,"0.00")) -> D+11.87 | M38: =COUNTIF($H$36:$H$71,">"&H38)+COUNTIF($H$36:H38,H38) -> 15 | N38: =ABS(H38) -> 11.87 | O38: =COUNTIF($N$36:$N$71,"<"&N38)+COUNTIF($N$36:N38,N38) -> 13 | P38: ='GOVERNOR DATA'!M6 -> 0.67 | Q38: ='GOVERNOR DATA'!N6 -> Prior Governor (2022) | R38: =H38-P38 -> 11.2 | S38: =B38-P38 -> 11.979439 | T38: =H38-B38 -> -0.77943852
A39: ='GOVERNOR DATA'!A7 -> Arkansas | B39: ='GOVERNOR DATA'!B7 -> -16.052228 | C39: =$D$5 -> -0.3 | D39: =2*('GOVERNOR DATA'!D7*('HOUSE DASHBOARD'!$B$14-42.4)+'GOVERNOR DATA'!E7*('HOUSE DASHBOARD'!$B$15-54.2)+'GOVERNOR DATA'!F7*('HOUSE DASHBOARD'!$B$16-85.4)+'GOVERNOR DATA'!G7*('HOUSE DASHBOARD'!$B$17-60.7)+'GOVERNOR DATA'!H7*('HOUSE DASHBOARD'!$B$18-53.5))/100 -> 0 | E39: =2*('GOVERNOR DATA'!I7*('HOUSE DASHBOARD'!$B$21-55.6)+(100-'GOVERNOR DATA'!I7)*('HOUSE DASHBOARD'!$B$22-44.9))/100 -> 0 | F39: =0 -> 0 | G39: =(D39+E39)/2 -> 0 | H39: ='GOVERNOR DATA'!C7+C39+G39 -> -16.6 | I39: =IF(H39>=0,"D","R") -> R | J39: ='GOVERNOR DATA'!K7 -> R | K39: =IF(I39=J39,"—",J39&" → "&I39) -> — | L39: =IF(H39>=0,"D+"&TEXT(H39,"0.00"),"R+"&TEXT(-H39,"0.00")) -> R+16.60 | M39: =COUNTIF($H$36:$H$71,">"&H39)+COUNTIF($H$36:H39,H39) -> 29 | N39: =ABS(H39) -> 16.6 | O39: =COUNTIF($N$36:$N$71,"<"&N39)+COUNTIF($N$36:N39,N39) -> 18 | P39: ='GOVERNOR DATA'!M7 -> -27.8 | Q39: ='GOVERNOR DATA'!N7 -> Prior Governor (2022) | R39: =H39-P39 -> 11.2 | S39: =B39-P39 -> 11.747772 | T39: =H39-B39 -> -0.54777166
A40: ='GOVERNOR DATA'!A8 -> California | B40: ='GOVERNOR DATA'!B8 -> 31.899894 | C40: =$D$5 -> -0.3 | D40: =2*('GOVERNOR DATA'!D8*('HOUSE DASHBOARD'!$B$14-42.4)+'GOVERNOR DATA'!E8*('HOUSE DASHBOARD'!$B$15-54.2)+'GOVERNOR DATA'!F8*('HOUSE DASHBOARD'!$B$16-85.4)+'GOVERNOR DATA'!G8*('HOUSE DASHBOARD'!$B$17-60.7)+'GOVERNOR DATA'!H8*('HOUSE DASHBOARD'!$B$18-53.5))/100 -> 0 | E40: =2*('GOVERNOR DATA'!I8*('HOUSE DASHBOARD'!$B$21-55.6)+(100-'GOVERNOR DATA'!I8)*('HOUSE DASHBOARD'!$B$22-44.9))/100 -> 0 | F40: =0 -> 0 | G40: =(D40+E40)/2 -> 0 | H40: ='GOVERNOR DATA'!C8+C40+G40 -> 29.98 | I40: =IF(H40>=0,"D","R") -> D | J40: ='GOVERNOR DATA'!K8 -> D | K40: =IF(I40=J40,"—",J40&" → "&I40) -> — | L40: =IF(H40>=0,"D+"&TEXT(H40,"0.00"),"R+"&TEXT(-H40,"0.00")) -> D+29.98 | M40: =COUNTIF($H$36:$H$71,">"&H40)+COUNTIF($H$36:H40,H40) -> 5 | N40: =ABS(H40) -> 29.98 | O40: =COUNTIF($N$36:$N$71,"<"&N40)+COUNTIF($N$36:N40,N40) -> 30 | P40: ='GOVERNOR DATA'!M8 -> 20.1 | Q40: ='GOVERNOR DATA'!N8 -> 2024 President (2024) | R40: =H40-P40 -> 9.88 | S40: =B40-P40 -> 11.799894 | T40: =H40-B40 -> -1.9198944
A41: ='GOVERNOR DATA'!A9 -> Colorado | B41: ='GOVERNOR DATA'!B9 -> 19.582218 | C41: =$D$5 -> -0.3 | D41: =2*('GOVERNOR DATA'!D9*('HOUSE DASHBOARD'!$B$14-42.4)+'GOVERNOR DATA'!E9*('HOUSE DASHBOARD'!$B$15-54.2)+'GOVERNOR DATA'!F9*('HOUSE DASHBOARD'!$B$16-85.4)+'GOVERNOR DATA'!G9*('HOUSE DASHBOARD'!$B$17-60.7)+'GOVERNOR DATA'!H9*('HOUSE DASHBOARD'!$B$18-53.5))/100 -> 0 | E41: =2*('GOVERNOR DATA'!I9*('HOUSE DASHBOARD'!$B$21-55.6)+(100-'GOVERNOR DATA'!I9)*('HOUSE DASHBOARD'!$B$22-44.9))/100 -> 0 | F41: =0 -> 0 | G41: =(D41+E41)/2 -> 0 | H41: ='GOVERNOR DATA'!C9+C41+G41 -> 20.88 | I41: =IF(H41>=0,"D","R") -> D | J41: ='GOVERNOR DATA'!K9 -> D | K41: =IF(I41=J41,"—",J41&" → "&I41) -> — | L41: =IF(H41>=0,"D+"&TEXT(H41,"0.00"),"R+"&TEXT(-H41,"0.00")) -> D+20.88 | M41: =COUNTIF($H$36:$H$71,">"&H41)+COUNTIF($H$36:H41,H41) -> 9 | N41: =ABS(H41) -> 20.88 | O41: =COUNTIF($N$36:$N$71,"<"&N41)+COUNTIF($N$36:N41,N41) -> 24 | P41: ='GOVERNOR DATA'!M9 -> 11 | Q41: ='GOVERNOR DATA'!N9 -> 2024 President (2024) | R41: =H41-P41 -> 9.88 | S41: =B41-P41 -> 8.5822175 | T41: =H41-B41 -> 1.2977825
A42: ='GOVERNOR DATA'!A10 -> Connecticut | B42: ='GOVERNOR DATA'!B10 -> 22.889764 | C42: =$D$5 -> -0.3 | D42: =2*('GOVERNOR DATA'!D10*('HOUSE DASHBOARD'!$B$14-42.4)+'GOVERNOR DATA'!E10*('HOUSE DASHBOARD'!$B$15-54.2)+'GOVERNOR DATA'!F10*('HOUSE DASHBOARD'!$B$16-85.4)+'GOVERNOR DATA'!G10*('HOUSE DASHBOARD'!$B$17-60.7)+'GOVERNOR DATA'!H10*('HOUSE DASHBOARD'!$B$18-53.5))/100 -> 0 | E42: =2*('GOVERNOR DATA'!I10*('HOUSE DASHBOARD'!$B$21-55.6)+(100-'GOVERNOR DATA'!I10)*('HOUSE DASHBOARD'!$B$22-44.9))/100 -> 0 | F42: =0 -> 0 | G42: =(D42+E42)/2 -> 0 | H42: ='GOVERNOR DATA'!C10+C42+G42 -> 24.1 | I42: =IF(H42>=0,"D","R") -> D | J42: ='GOVERNOR DATA'!K10 -> D | K42: =IF(I42=J42,"—",J42&" → "&I42) -> — | L42: =IF(H42>=0,"D+"&TEXT(H42,"0.00"),"R+"&TEXT(-H42,"0.00")) -> D+24.10 | M42: =COUNTIF($H$36:$H$71,">"&H42)+COUNTIF($H$36:H42,H42) -> 7 | N42: =ABS(H42) -> 24.1 | O42: =COUNTIF($N$36:$N$71,"<"&N42)+COUNTIF($N$36:N42,N42) -> 26 | P42: ='GOVERNOR DATA'!M10 -> 12.9 | Q42: ='GOVERNOR DATA'!N10 -> Prior Governor (2022) | R42: =H42-P42 -> 11.2 | S42: =B42-P42 -> 9.9897641 | T42: =H42-B42 -> 1.2102359
A43: ='GOVERNOR DATA'!A11 -> Florida | B43: ='GOVERNOR DATA'!B11 -> -2.0562831 | C43: =$D$5 -> -0.3 | D43: =2*('GOVERNOR DATA'!D11*('HOUSE DASHBOARD'!$B$14-42.4)+'GOVERNOR DATA'!E11*('HOUSE DASHBOARD'!$B$15-54.2)+'GOVERNOR DATA'!F11*('HOUSE DASHBOARD'!$B$16-85.4)+'GOVERNOR DATA'!G11*('HOUSE DASHBOARD'!$B$17-60.7)+'GOVERNOR DATA'!H11*('HOUSE DASHBOARD'!$B$18-53.5))/100 -> 0 | E43: =2*('GOVERNOR DATA'!I11*('HOUSE DASHBOARD'!$B$21-55.6)+(100-'GOVERNOR DATA'!I11)*('HOUSE DASHBOARD'!$B$22-44.9))/100 -> 0 | F43: =0 -> 0 | G43: =(D43+E43)/2 -> 0 | H43: ='GOVERNOR DATA'!C11+C43+G43 -> -3.22 | I43: =IF(H43>=0,"D","R") -> R | J43: ='GOVERNOR DATA'!K11 -> R | K43: =IF(I43=J43,"—",J43&" → "&I43) -> — | L43: =IF(H43>=0,"D+"&TEXT(H43,"0.00"),"R+"&TEXT(-H43,"0.00")) -> R+3.22 | M43: =COUNTIF($H$36:$H$71,">"&H43)+COUNTIF($H$36:H43,H43) -> 24 | N43: =ABS(H43) -> 3.22 | O43: =COUNTIF($N$36:$N$71,"<"&N43)+COUNTIF($N$36:N43,N43) -> 5 | P43: ='GOVERNOR DATA'!M11 -> -13.1 | Q43: ='GOVERNOR DATA'!N11 -> 2024 President (2024) | R43: =H43-P43 -> 9.88 | S43: =B43-P43 -> 11.043717 | T43: =H43-B43 -> -1.1637169
A44: ='GOVERNOR DATA'!A12 -> Georgia | B44: ='GOVERNOR DATA'!B12 -> 8.0635341 | C44: =$D$5 -> -0.3 | D44: =2*('GOVERNOR DATA'!D12*('HOUSE DASHBOARD'!$B$14-42.4)+'GOVERNOR DATA'!E12*('HOUSE DASHBOARD'!$B$15-54.2)+'GOVERNOR DATA'!F12*('HOUSE DASHBOARD'!$B$16-85.4)+'GOVERNOR DATA'!G12*('HOUSE DASHBOARD'!$B$17-60.7)+'GOVERNOR DATA'!H12*('HOUSE DASHBOARD'!$B$18-53.5))/100 -> 0 | E44: =2*('GOVERNOR DATA'!I12*('HOUSE DASHBOARD'!$B$21-55.6)+(100-'GOVERNOR DATA'!I12)*('HOUSE DASHBOARD'!$B$22-44.9))/100 -> 0 | F44: =0 -> 0 | G44: =(D44+E44)/2 -> 0 | H44: ='GOVERNOR DATA'!C12+C44+G44 -> 7.68 | I44: =IF(H44>=0,"D","R") -> D | J44: ='GOVERNOR DATA'!K12 -> D | K44: =IF(I44=J44,"—",J44&" → "&I44) -> — | L44: =IF(H44>=0,"D+"&TEXT(H44,"0.00"),"R+"&TEXT(-H44,"0.00")) -> D+7.68 | M44: =COUNTIF($H$36:$H$71,">"&H44)+COUNTIF($H$36:H44,H44) -> 19 | N44: =ABS(H44) -> 7.68 | O44: =COUNTIF($N$36:$N$71,"<"&N44)+COUNTIF($N$36:N44,N44) -> 8 | P44: ='GOVERNOR DATA'!M12 -> -2.2 | Q44: ='GOVERNOR DATA'!N12 -> 2024 President (2024) | R44: =H44-P44 -> 9.88 | S44: =B44-P44 -> 10.263534 | T44: =H44-B44 -> -0.38353409
A45: ='GOVERNOR DATA'!A13 -> Hawaii | B45: ='GOVERNOR DATA'!B13 -> 41.044565 | C45: =$D$5 -> -0.3 | D45: =2*('GOVERNOR DATA'!D13*('HOUSE DASHBOARD'!$B$14-42.4)+'GOVERNOR DATA'!E13*('HOUSE DASHBOARD'!$B$15-54.2)+'GOVERNOR DATA'!F13*('HOUSE DASHBOARD'!$B$16-85.4)+'GOVERNOR DATA'!G13*('HOUSE DASHBOARD'!$B$17-60.7)+'GOVERNOR DATA'!H13*('HOUSE DASHBOARD'!$B$18-53.5))/100 -> 0 | E45: =2*('GOVERNOR DATA'!I13*('HOUSE DASHBOARD'!$B$21-55.6)+(100-'GOVERNOR DATA'!I13)*('HOUSE DASHBOARD'!$B$22-44.9))/100 -> 0 | F45: =0 -> 0 | G45: =(D45+E45)/2 -> 0 | H45: ='GOVERNOR DATA'!C13+C45+G45 -> 37.6 | I45: =IF(H45>=0,"D","R") -> D | J45: ='GOVERNOR DATA'!K13 -> D | K45: =IF(I45=J45,"—",J45&" → "&I45) -> — | L45: =IF(H45>=0,"D+"&TEXT(H45,"0.00"),"R+"&TEXT(-H45,"0.00")) -> D+37.60 | M45: =COUNTIF($H$36:$H$71,">"&H45)+COUNTIF($H$36:H45,H45) -> 3 | N45: =ABS(H45) -> 37.6 | O45: =COUNTIF($N$36:$N$71,"<"&N45)+COUNTIF($N$36:N45,N45) -> 33 | P45: ='GOVERNOR DATA'!M13 -> 26.4 | Q45: ='GOVERNOR DATA'!N13 -> Prior Governor (2022) | R45: =H45-P45 -> 11.2 | S45: =B45-P45 -> 14.644565 | T45: =H45-B45 -> -3.4445647
A46: ='GOVERNOR DATA'!A14 -> Idaho | B46: ='GOVERNOR DATA'!B14 -> -29.891132 | C46: =$D$5 -> -0.3 | D46: =2*('GOVERNOR DATA'!D14*('HOUSE DASHBOARD'!$B$14-42.4)+'GOVERNOR DATA'!E14*('HOUSE DASHBOARD'!$B$15-54.2)+'GOVERNOR DATA'!F14*('HOUSE DASHBOARD'!$B$16-85.4)+'GOVERNOR DATA'!G14*('HOUSE DASHBOARD'!$B$17-60.7)+'GOVERNOR DATA'!H14*('HOUSE DASHBOARD'!$B$18-53.5))/100 -> 0 | E46: =2*('GOVERNOR DATA'!I14*('HOUSE DASHBOARD'!$B$21-55.6)+(100-'GOVERNOR DATA'!I14)*('HOUSE DASHBOARD'!$B$22-44.9))/100 -> 0 | F46: =0 -> 0 | G46: =(D46+E46)/2 -> 0 | H46: ='GOVERNOR DATA'!C14+C46+G46 -> -29 | I46: =IF(H46>=0,"D","R") -> R | J46: ='GOVERNOR DATA'!K14 -> R | K46: =IF(I46=J46,"—",J46&" → "&I46) -> — | L46: =IF(H46>=0,"D+"&TEXT(H46,"0.00"),"R+"&TEXT(-H46,"0.00")) -> R+29.00 | M46: =COUNTIF($H$36:$H$71,">"&H46)+COUNTIF($H$36:H46,H46) -> 34 | N46: =ABS(H46) -> 29 | O46: =COUNTIF($N$36:$N$71,"<"&N46)+COUNTIF($N$36:N46,N46) -> 29 | P46: ='GOVERNOR DATA'!M14 -> -40.2 | Q46: ='GOVERNOR DATA'!N14 -> Prior Governor (2022) | R46: =H46-P46 -> 11.2 | S46: =B46-P46 -> 10.308868 | T46: =H46-B46 -> 0.89113174
